Workbook

Sheet Tổng quan
A1: LAMVI — Tiến độ việc của client
A2: Tự cập nhật theo cột "Trạng thái" ở tab Task tracker.
A4: Tổng số việc | B4: =COUNTA('Task tracker'!A2:A98)
A5: Đã xong | B5: =COUNTIF('Task tracker'!G2:G98,"Xong")
A6: Tỉ lệ hoàn thành | B6: =IF(B4=0,0,B5/B4)
A7: Việc chặn go-live còn lại | B7: =COUNTIFS('Task tracker'!E2:E98,"🔴 Chặn go-live",'Task tracker'!G2:G98,"<>Xong")
A8: Quá hạn (chưa xong) | B8: =SUMPRODUCT(('Task tracker'!I2:I98<>"")*('Task tracker'!I2:I98<TODAY())*('Task tracker'!G2:G98<>"Xong"))
A10: Theo trạng thái
A11: Chưa bắt đầu | B11: =COUNTIF('Task tracker'!G2:G98,A11)
A12: Đang làm | B12: =COUNTIF('Task tracker'!G2:G98,A12)
A13: Chờ duyệt | B13: =COUNTIF('Task tracker'!G2:G98,A13)
A14: Bị chặn | B14: =COUNTIF('Task tracker'!G2:G98,A14)
A15: Xong | B15: =COUNTIF('Task tracker'!G2:G98,A15)
A17: Theo ưu tiên | B17: Tổng | C17: Xong
A18: 🔴 Chặn go-live | B18: =COUNTIF('Task tracker'!E2:E98,A18) | C18: =COUNTIFS('Task tracker'!E2:E98,A18,'Task tracker'!G2:G98,"Xong")
A19: 🟠 Trước khi mở bán | B19: =COUNTIF('Task tracker'!E2:E98,A19) | C19: =COUNTIFS('Task tracker'!E2:E98,A19,'Task tracker'!G2:G98,"Xong")
A20: 🟡 Làm sau được | B20: =COUNTIF('Task tracker'!E2:E98,A20) | C20: =COUNTIFS('Task tracker'!E2:E98,A20,'Task tracker'!G2:G98,"Xong")
A23: Theo nhóm | B23: Tổng | C23: Xong | D23: Còn lại
A24: Thương hiệu | B24: =COUNTIF('Task tracker'!B2:B98,A24) | C24: =COUNTIFS('Task tracker'!B2:B98,A24,'Task tracker'!G2:G98,"Xong") | D24: =B24-C24
A25: Sản phẩm | B25: =COUNTIF('Task tracker'!B2:B98,A25) | C25: =COUNTIFS('Task tracker'!B2:B98,A25,'Task tracker'!G2:G98,"Xong") | D25: =B25-C25
A26: Bộ sưu tập | B26: =COUNTIF('Task tracker'!B2:B98,A26) | C26: =COUNTIFS('Task tracker'!B2:B98,A26,'Task tracker'!G2:G98,"Xong") | D26: =B26-C26
A27: Trang chủ | B27: =COUNTIF('Task tracker'!B2:B98,A27) | C27: =COUNTIFS('Task tracker'!B2:B98,A27,'Task tracker'!G2:G98,"Xong") | D27: =B27-C27
A28: Các trang khác | B28: =COUNTIF('Task tracker'!B2:B98,A28) | C28: =COUNTIFS('Task tracker'!B2:B98,A28,'Task tracker'!G2:G98,"Xong") | D28: =B28-C28
A29: Mây (AI) | B29: =COUNTIF('Task tracker'!B2:B98,A29) | C29: =COUNTIFS('Task tracker'!B2:B98,A29,'Task tracker'!G2:G98,"Xong") | D29: =B29-C29
A30: Lô đèn & QR | B30: =COUNTIF('Task tracker'!B2:B98,A30) | C30: =COUNTIFS('Task tracker'!B2:B98,A30,'Task tracker'!G2:G98,"Xong") | D30: =B30-C30
A31: Doanh nghiệp & pháp lý | B31: =COUNTIF('Task tracker'!B2:B98,A31) | C31: =COUNTIFS('Task tracker'!B2:B98,A31,'Task tracker'!G2:G98,"Xong") | D31: =B31-C31
A32: Vận hành bán hàng | B32: =COUNTIF('Task tracker'!B2:B98,A32) | C32: =COUNTIFS('Task tracker'!B2:B98,A32,'Task tracker'!G2:G98,"Xong") | D32: =B32-C32
A33: Email | B33: =COUNTIF('Task tracker'!B2:B98,A33) | C33: =COUNTIFS('Task tracker'!B2:B98,A33,'Task tracker'!G2:G98,"Xong") | D33: =B33-C33
A34: Tài khoản dịch vụ | B34: =COUNTIF('Task tracker'!B2:B98,A34) | C34: =COUNTIFS('Task tracker'!B2:B98,A34,'Task tracker'!G2:G98,"Xong") | D34: =B34-C34
A35: Dịch thuật | B35: =COUNTIF('Task tracker'!B2:B98,A35) | C35: =COUNTIFS('Task tracker'!B2:B98,A35,'Task tracker'!G2:G98,"Xong") | D35: =B35-C35
A36: Quyết định nghiệp vụ | B36: =COUNTIF('Task tracker'!B2:B98,A36) | C36: =COUNTIFS('Task tracker'!B2:B98,A36,'Task tracker'!G2:G98,"Xong") | D36: =B36-C36
A37: Admin & vận hành | B37: =COUNTIF('Task tracker'!B2:B98,A37) | C37: =COUNTIFS('Task tracker'!B2:B98,A37,'Task tracker'!G2:G98,"Xong") | D37: =B37-C37

Sheet Task tracker
A1: Mã | B1: Nhóm | C1: Việc cần làm | D1: Chi tiết / cần gửi gì | E1: Ưu tiên | F1: Tham chiếu | G1: Trạng thái | H1: Người phụ trách (client) | I1: Hạn (client điền) | J1: Ngày xong | K1: File / link đã gửi | L1: Ghi chú
A2: 1.1 | B2: Thương hiệu | C2: Gửi bộ logo chính thức | D2: SVG + PNG nền trong; bản ngang/dọc/một màu (trắng, đen). Hiện chỉ là chữ triện dev vẽ tạm | E2: 🔴 Chặn go-live | F2: §1 | G2: Chưa bắt đầu
A3: 1.2 | B3: Thương hiệu | C3: Gửi favicon / icon tab | D3: 32×32, 180×180 (iOS), 512×512. Hiện đang là logo mặc định của Vite | E3: 🔴 Chặn go-live | F3: §1 | G3: Chưa bắt đầu
A4: 1.3 | B4: Thương hiệu | C4: Xác nhận brand guideline | D4: Bảng màu, quy tắc dùng logo — đối chiếu docs/BRAND_GUIDELINE.md | E4: 🟠 Trước khi mở bán | F4: §1 | G4: Chưa bắt đầu
A5: 1.4 | B5: Thương hiệu | C5: Xác nhận / gửi font chữ | D5: Fraunces + Be Vietnam Pro hoặc font bản quyền khác (kèm giấy phép web) | E5: 🟡 Làm sau được | F5: §1 | G5: Chưa bắt đầu
A6: 1.5 | B6: Thương hiệu | C6: Chốt tagline & thông điệp chính thức (VI/EN/ZH) | E6: 🟠 Trước khi mở bán | F6: §1 | G6: Chưa bắt đầu
A7: 1.6 | B7: Thương hiệu | C7: Gửi ảnh chia sẻ MXH (og:image) 1200×630 | E7: 🟠 Trước khi mở bán | F7: §1 | G7: Chưa bắt đầu
A8: 1.7 | B8: Thương hiệu | C8: Gửi banner email (~1200×300) | E8: 🟡 Làm sau được | F8: §1 | G8: Chưa bắt đầu
A9: 1.8 | B9: Thương hiệu | C9: Xác nhận / gửi thiết kế mascot Mây | D9: SVG, biểu cảm: chào, đang nghĩ, ốm, nghỉ | E9: 🟡 Làm sau được | F9: §1 | G9: Chưa bắt đầu
A10: 1.9 | B10: Thương hiệu | C10: Gửi hoạ tiết / triện / chữ ký của xưởng (nếu có) | E10: 🟡 Làm sau được | F10: §1 | G10: Chưa bắt đầu
A11: 1.10 | B11: Thương hiệu | C11: Viết tone of voice | D11: 5–10 câu mẫu nên/không nên nói; cách xưng hô; có dùng emoji không | E11: 🟠 Trước khi mở bán | F11: §1 | G11: Chưa bắt đầu
A12: 2.1 | B12: Sản phẩm | C12: Điền bảng sản phẩm | D12: Tab "Sản phẩm (chữ)" + "Sản phẩm (giá, thông số)" trong file nội dung: tên, mô tả, giá đã gồm VAT, tồn kho | E12: 🔴 Chặn go-live | F12: §2 | G12: Chờ duyệt | L12: 13/10: 5 đèn thật đã lên web (tên, mô tả, thông số, giá tạm). Duyệt tab "Sản phẩm" trong file nội dung
A13: 2.2 | B13: Sản phẩm | C13: Điền 6 thông số mỗi đèn | D13: Kích thước · Chất liệu · Nguồn sáng · Cân nặng · Thời gian làm · Bảo quản | E13: 🔴 Chặn go-live | F13: §2 | G13: Chờ duyệt | L13: 13/10: đã điền 4/6 thông số (kích thước, chất liệu, nguồn sáng, thời gian làm). Thiếu cân nặng, bảo quản → xem 2.7
A14: 2.3 | B14: Sản phẩm | C14: Chụp & gửi ảnh sản phẩm thật | D14: Vuông ≥1200×1200; đèn bật + tắt; ảnh bối cảnh + chi tiết; kèm alt text tiếng Việt và quyền sử dụng ảnh | E14: 🔴 Chặn go-live | F14: §2 | G14: Chưa bắt đầu
A15: 2.4 | B15: Sản phẩm | C15: Chốt bộ Sum Vầy gồm đèn nào, giá lẻ từng đèn (Q-05) | E15: 🔴 Chặn go-live | F15: §2 | G15: Xong | L15: Không còn áp dụng: không có bộ Sum Vầy (D-104)
A16: 2.5 | B16: Sản phẩm | C16: Chốt có bán sẵn hay làm theo đơn, số tồn ban đầu | E16: 🔴 Chặn go-live | F16: §2 | G16: Chưa bắt đầu
A17: 2.6 | B17: Sản phẩm | C17: Chốt giá thật từng mẫu trong 5 đèn | D17: Hiện đang là giá tạm 1.400.000đ cho cả 5 (trung điểm 1,3–1,5 triệu của báo cáo, chưa kiểm chứng) | E17: 🔴 Chặn go-live | F17: §2 | G17: Chưa bắt đầu
A18: 2.7 | B18: Sản phẩm | C18: Gửi cân nặng và cách bảo quản của đèn | D18: Hai trong 6 thông số còn trống; xác nhận kích thước chốt (báo cáo ghi 12×12×20 cm là prototype) | E18: 🔴 Chặn go-live | F18: §2 | G18: Chưa bắt đầu
A19: 2.8 | B19: Sản phẩm | C19: Viết mô tả dài / câu chuyện cho từng đèn | D19: Content Plan đã có bài dài cho 5 đèn; web hiện chỉ có mô tả 1 câu — cho biết dùng nguyên bài hay rút gọn | E19: 🟠 Trước khi mở bán | F19: §2 | G19: Chưa bắt đầu
A20: 3.1 | B20: Bộ sưu tập | C20: Điền nội dung mỗi bộ sưu tập | D20: Tab "Bộ sưu tập": tên, mô tả, câu chuyện; ảnh bìa ngang ≥1600px | E20: 🔴 Chặn go-live | F20: §3 | G20: Chờ duyệt | L20: 13/10: 1 bộ "Bộ sưu tập đầu tiên" + câu chuyện bộ do dev soạn từ Content Plan
A21: 3.2 | B21: Bộ sưu tập | C21: Chốt có thêm category/bộ lọc khác không | D21: Theo dịp (Tết, Trung thu, tân gia…), theo không gian (bàn trà, phòng ngủ…), theo giá | E21: 🟠 Trước khi mở bán | F21: §3 | G21: Chưa bắt đầu
A22: 3.3 | B22: Bộ sưu tập | C22: Viết nội dung phần thưởng cốt truyện cho Gallery / chăn Đông Hồ | D22: Và xác nhận còn muốn giữ tính năng này | E22: 🟠 Trước khi mở bán | F22: §3 | G22: Chưa bắt đầu
A23: 4.1 | B23: Trang chủ | C23: Duyệt/sửa Hero (HOME-02) + gửi ảnh hoặc video hero thật | D23: Xác nhận "làng nghề trăm năm" đúng sự thật | E23: 🔴 Chặn go-live | F23: §4 | G23: Chưa bắt đầu
A24: 4.2 | B24: Trang chủ | C24: Duyệt dải chữ chạy (HOME-03) | E24: 🟡 Làm sau được | F24: §4 | G24: Chưa bắt đầu
A25: 4.3 | B25: Trang chủ | C25: Gửi số liệu thật + câu chuyện làng nghề (HOME-04) | D25: 79+ năm, 10 nghệ nhân hiện là số MẪU | E25: 🔴 Chặn go-live | F25: §4 | G25: Chờ duyệt | L25: 13/10: đã thay số mẫu bằng 5 đèn / 3 chặng / 1 lời chúc. Cần câu chuyện làng nghề thật
A26: 4.4 | B26: Trang chủ | C26: Khối Nghệ nhân (HOME-05): gửi nhân vật thật hoặc bỏ khối | D26: Tên, ảnh chân dung, câu nói, 32 năm / 4.000+ đèn là mẫu; cần văn bản đồng ý của nghệ nhân | E26: 🔴 Chặn go-live | F26: §4 | G26: Chờ duyệt | L26: 13/10: đã dùng tên Nghệ nhân Ưu tú Nguyễn Hữu Quả, bỏ câu trích + số liệu mẫu. Cần ảnh + đồng ý → xem 8.11
A27: 4.5 | B27: Trang chủ | C27: Duyệt câu giới thiệu bộ sưu tập (HOME-06) | E27: 🟠 Trước khi mở bán | F27: §4 | G27: Chưa bắt đầu
A28: 4.6 | B28: Trang chủ | C28: Lookbook (HOME-07): gửi ảnh thật + chốt 5 tên màu | E28: 🟠 Trước khi mở bán | F28: §4 | G28: Chờ duyệt | L28: 13/10: lookbook = 5 tên đèn. Cần ảnh thật
A29: 4.7 | B29: Trang chủ | C29: Hành trình thủ công (HOME-08): xác nhận 4 bước + ảnh/video từng bước | E29: 🟠 Trước khi mở bán | F29: §4 | G29: Chờ duyệt | L29: 13/10: 4 bước đã đổi theo Content Plan. Cần xác nhận + ảnh/video
A30: 4.8 | B30: Trang chủ | C30: Duyệt khối Trải nghiệm QR (HOME-09) | D30: Nhất là câu thời hạn lưu 30 ngày | E30: 🟠 Trước khi mở bán | F30: §4 | G30: Chờ duyệt | L30: 13/10: đã sửa QR chỉ ở thiệp cảm ơn (D-104)
A31: 4.9 | B31: Trang chủ | C31: Testimonials (HOME-10): gửi đánh giá thật + đồng ý của người viết, hoặc bỏ | D31: Hiện đang ẩn | E31: 🟡 Làm sau được | F31: §4 | G31: Chưa bắt đầu
A32: 4.10 | B32: Trang chủ | C32: Duyệt 5 FAQ + thêm câu hỏi thực tế khách hay hỏi (HOME-11) | D32: Tab "FAQ" | E32: 🔴 Chặn go-live | F32: §4 | G32: Chờ duyệt | L32: 13/10: FAQ 9 câu (thêm 4 câu). Cần thêm câu hỏi thực tế
A33: 4.11 | B33: Trang chủ | C33: Duyệt tiêu đề/mô tả SEO hiện trên Google | E33: 🟠 Trước khi mở bán | F33: §4 | G33: Chưa bắt đầu
A34: 4.12 | B34: Trang chủ | C34: Chốt giữ hay bỏ form newsletter (G-11) | E34: 🟡 Làm sau được | F34: §4 | G34: Chưa bắt đầu
A35: 5.1 | B35: Các trang khác | C35: Duyệt chữ Cửa hàng / Chi tiết sản phẩm / Bộ sưu tập | D35: Tab "Nội dung web" | E35: 🟠 Trước khi mở bán | F35: §5 | G35: Chưa bắt đầu
A36: 5.2 | B36: Các trang khác | C36: Duyệt chữ Giỏ hàng / Thanh toán / Đơn hàng | E36: 🟠 Trước khi mở bán | F36: §5 | G36: Chưa bắt đầu
A37: 5.3 | B37: Các trang khác | C37: Duyệt chữ Đăng nhập / Đăng ký / Quên mật khẩu + gửi ảnh nền thương hiệu | E37: 🟠 Trước khi mở bán | F37: §5 | G37: Chưa bắt đầu
A38: 5.4 | B38: Các trang khác | C38: Duyệt chữ trang người nhận mở lời chúc (QR-GIFT) | D38: Điểm chạm cảm xúc nhất — nên do copywriter viết | E38: 🟠 Trước khi mở bán | F38: §5 | G38: Chưa bắt đầu
A39: 5.5 | B39: Các trang khác | C39: Duyệt chữ Liên hệ, 404, bảo trì | E39: 🟠 Trước khi mở bán | F39: §5 | G39: Chưa bắt đầu
A40: 5.6 | B40: Các trang khác | C40: Duyệt tên các trạng thái đơn hàng | D40: Chờ thanh toán, Đang làm, Đã đóng gói, Đã gửi, Đã giao, Đã huỷ, Hoàn tiền | E40: 🟠 Trước khi mở bán | F40: §5 | G40: Chưa bắt đầu
...
